Workbook

Sheet 前置信息
A2: 容积率 | B2: 小于2.5
A3: 地下室层数 | B3: 2
A4: 桩基形式 | B4: 灌注桩
A5: 水平支撑层数 | B5: 0
A6: 首开示范区面积 | B6: 小于7000㎡
A7: 有无架空层 | B7: 无
A8: 地上最高层数 | B8: 16
A9: 有无开发贷 | B9: 无
A10: 交付形式 | B10: 精装
A11: 有无户内改造 | B11: 无
A12: 外立面形式 | B12: 保温涂料

Sheet 节点计划 (终稿)
D2: 项目里程碑节点、一级节点、二级节点清单（2026）
A3: 里程碑序号 | B3: 一级节点序号 | C3: 二级节点序号 | D3: 类别 | E3: 项目开发节点名称 | F3: 主责专业 | G3: 项目内控开始时间 | H3: 工期 | I3: 项目内控完成时间 | J3: 考核版完成时间 | K3: 履约版完成时间 | L3: 计划模板工期完成时间（仅供参考，含批量精装） | M3: 集团标准期量描述 （18F高层） | N3: 集团标准期量描述 （4F及以下） | O3: 集团标准期量描述 （6F叠拼） | P3: 集团标准期量描述 （8F洋房） | Q3: 集团标准期量描述 （11F小高层） | R3: 集团标准期量描述 （27F高层） | S3: 集团标准期量描述 （33F高层） | T3: 定义/成果/记录表单 | U3: 支持性文件
B4: 1 | D4: 一级 | E4: 代建合同签订 | F4: 发展 | M4: 代建合同签订 | N4: 代建合同签订 | O4: 代建合同签订 | P4: 代建合同签订 | Q4: 代建合同签订 | R4: 代建合同签订 | S4: 代建合同签订 | T4: 代建合同签约文本
B5: 2 | D5: 一级 | E5: 取得《国有土地使用权证》 | F5: 前期 | T5: 《国有土地使用证》
B6: 3 | D6: 一级 | E6: 项目启动 | F6: 发展 | L6: 44914 | M6: 土地确权并定金支付 | N6: 土地确权并定金支付 | O6: 基准点 | P6: 基准点 | Q6: 基准点 | R6: 基准点 | S6: 基准点 | T6: 签约、支付首笔代建费定金、土地已确权
B7: 4 | D7: 一级 | E7: 完成项目交底会 | F7: 发展 | L7: =L6+3 -> 44917 | M7: T0后3天内 | N7: T0后3天内 | O7: T0后3天内 | P7: T0后3天内 | Q7: T0后3天内 | R7: T0后3天内 | S7: T0后3天内 | T7: 项目交底会报告及成果 | U7: GTBG84100-2022《项目运营手册运营管理弦》
B8: 5 | D8: 一级 | E8: 完成项目定位会 | F8: 客研 | L8: =L6+10 -> 44924 | M8: T0后10天内 | N8: T0后10天内 | O8: T0后10天内 | P8: T0后10天内 | Q8: T0后10天内 | R8: T0后10天内 | S8: T0后10天内 | T8: 项目市场分析及定位报告；集团定位评审会会议纪要；定位意见修改反馈 | U8: GTBO51000-2021《项目运营手册营销弦》
B9: 6 | D9: 一级 | E9: 规划、建筑设计合同签订 | F9: 设计 | L9: =L6+10 -> 44924 | M9: T0后10天内 | N9: T0后10天内 | O9: T0后10天内 | P9: T0后10天内 | Q9: T0后10天内 | R9: T0后10天内 | S9: T0后10天内 | T9: 1、规划建筑设计合同 2、规划建筑设计单位选择报告 3、设计供方考察报告（新供方） | U9: 1、GTBG91100-2021 《规划设计类供方管理标准》 2、GTBO21100-2021 《项目运营手册设计弦之规划设计分弦》 3、GTBG92601-2018 《同步设计操作手册》 4、GTBG91100-2021 《规划设计供方管理标准 》
C10: 1 | D10: 二级 | E10: 精装设计单位选择及合同签订 | F10: 精装修 | L10: =L6+10 -> 44924 | M10: T0后10天 | N10: T0后10天 | O10: T0后10天 | P10: T0后10天 | Q10: T0后10天 | R10: T0后10天 | S10: T0后10天 | T10: 1、精装修设计合同 2、精装修设计单位选择报告 3、设计供方考察报告（新供方） | U10: 1、GTBG91300-2021 《精装修设计类供方管理标准》 2、GTBO24100-2021 《项目运营手册设计弦之精装修设计分弦》 3、GTBG92601-2018 《同步设计操作手册》
C11: 2 | D11: 二级 | E11: 景观设计单位选择及合同签订 | F11: 景观 | L11: =L6+10 -> 44924 | M11: T0后10天 | N11: T0后10天 | O11: T0后10天 | P11: T0后10天 | Q11: T0后10天 | R11: T0后10天 | S11: T0后10天 | T11: 1、景观设计合同 2、景观设计单位选择报告 3、设计供方考察报告（新供方） | U11: 1、GTBG91200-2021 《景观设计类供方管理标准》 2、GTBO23100-2021 《项目运营手册设计弦之景观设计分弦》
C12: 3 | D12: 二级 | E12: 规划建筑设计任务书编制及修订 | F12: 设计 | L12: =L6+10 -> 44924 | M12: T0后10天 | N12: T0后10天 | O12: T0后10天 | P12: T0后10天 | Q12: T0后10天 | R12: T0后10天 | S12: T0后10天 | T12: 规划建筑设计任务书。项目启动后10天内完成定位，30天完成方案设计 | U12: 1、GTBO21100-2021 《项目运营手册设计弦之规划设计分弦》
C13: 4 | D13: 二级 | E13: 完成样板房/区、销展中心定位及选址 | F13: 营销 | L13: =L6+10 -> 44924 | M13: T0后10天 | N13: T0后10天 | O13: T0后10天 | P13: T0后10天 | Q13: T0后10天 | R13: T0后10天 | S13: T0后10天 | T13: 选址和定位方案 | U13: 会议评审流转记录
C14: 5 | D14: 二级 | E14: 智能化设计单位选择及合同签订 | F14: 智能化 | L14: =L6+10 -> 44924 | M14: T0后10天 | N14: T0后10天 | O14: T0后10天 | P14: T0后10天 | Q14: T0后10天 | R14: T0后10天 | S14: T0后10天 | T14: 1、智能化设计单位选择请示报告 2、智能化设计合同 | U14: 1、GTBO22100-2021《项目运营手册设计弦之专项设计分弦》
C15: 6 | D15: 二级 | E15: 专项设计（幕墙、门窗、基坑围护等）单位选择及合同签订 | F15: 设计 | L15: =L6+10 -> 44924 | M15: T0后10天 | N15: T0后10天 | O15: T0后10天 | P15: T0后10天 | Q15: T0后10天 | R15: T0后10天 | S15: T0后10天 | T15: 1、幕墙门窗设计任务书 2、专项设计合同 | U15: 1、GTBG91100-2021 《规划设计类供方管理标准》 2、GTBO21100-2021 《项目运营手册设计弦之规划设计分弦》 3、GTBG92601-2018 《同步设计操作手册》
A16: 1 | D16: 里程碑 | E16: 经营策划会 | F16: 运营 | L16: =L6+30 -> 44944 | M16: T0后30天内 | N16: T0后30天内 | O16: T0后30天内 | P16: T0后30天内 | Q16: T0后30天内 | R16: T0后30天内 | S16: T0后30天内 | T16: 项目经营策划会报告及成果 | U16: GTBG84100-2022《项目运营手册运营管理弦》
C17: 7 | D17: 二级 | E17: 地质详勘完成（首开区） | F17: 工程 | L17: =L6+30 -> 44944 | M17: T0后30天内 | N17: T0后30天内 | O17: T0后30天内 | P17: T0后30天内 | Q17: T0后30天内 | R17: T0后30天内 | S17: T0后30天内 | T17: 提供首开区阶段报告
B18: 7 | D18: 一级 | E18: 规划、建筑方案设计通过集团评审 | F18: 设计 | L18: =L6+35 -> 44949 | M18: T0后35天 | N18: T0后35天 | O18: T0后35天 | P18: T0后35天 | Q18: T0后35天 | R18: T0后35天 | S18: T0后35天 | T18: 1、《评审会议纪要》 2、《绿城管理集团图审核心点审查表》 3、《绿城管理集团定位复核审查表》 4、《项目设计规范及报批信息落实表》 5、《预评审意见表》 6、《意见落实情况表》 7、同步设计落实情况 8、修改完善的方案文本（必须含CAD、效果图） | U18: 1、GTBO21100-2021 《项目运营手册设计弦之规划设计分弦》 2、GTBG92600-2018 《设计评审管理规定》 3、GTBG92601-2018 《同步设计操作手册》 4、GTBP13004-2020 《住宅项目建筑施工图评审要点》 5、GTBP5200X 《建筑工程营造工艺工法标准-XX篇》
C19: 8 | D19: 二级 | E19: 五通一平检查 | F19: 工程 | L19: =L6+40 -> 44954 | M19: T0后40天内 | N19: T0后40天内 | O19: T0后40天内 | P19: T0后40天内 | Q19: T0后40天内 | R19: T0后40天内 | S19: T0后40天内 | T19: 现场五通一平检查表 | U19: 1、GTBO31100-2017B《项目运营手册工程弦之建安分弦》-《31108 五通一平节点标准》
C20: 9 | D20: 二级 | E20: 样板区景观方案设计完成并通过评审 | F20: 景观 | L20: =L82-150 -> 44974 | M20: 开放前150天 | N20: 开放前150天 | O20: 开放前150天 | P20: 开放前150天 | Q20: 开放前150天 | R20: 开放前150天 | S20: 开放前150天 | T20: 1、景观样板区方案设计成果； 2、样板区方案评审会会议纪要； 3、绿城管理集团图审核心点审查表； | U20: 1、GTBO23100-2021 《项目运营手册设计弦之景观设计分弦》； 2、GTBP33100-2020 《景观设计评审要点》； 3、各类管控主体《管理审批权限表》；
C21: 10 | D21: 二级 | E21: 拆迁完成 | F21: 前期 | L21: =L6+60 -> 44974 | M21: T0后60天 | N21: T0后60天 | O21: T0后60天 | P21: T0后60天 | Q21: T0后60天 | R21: T0后60天 | S21: T0后60天 | T21: 地块附着物拆迁完成移交施工
C22: 11 | D22: 二级 | E22: 营销团队到岗/广告公司确定 | F22: 营销 | L22: =L93-180 -> 44974 | M22: 首次开盘前180天 | N22: 首次开盘前180天 | O22: 首次开盘前180天 | P22: 首次开盘前180天 | Q22: 首次开盘前180天 | R22: 首次开盘前180天 | S22: 首次开盘前180天 | T22: 方案和审批记录 | U22: 案名申请文件
C23: 12 | D23: 二级 | E23: 合约规划 | F23: 成本 | L23: =L40+15 -> 45017 | M23: 方案版目标成本审批后15天 | N23: 方案版目标成本审批后15天 | O23: 方案版目标成本审批后15天 | P23: 方案版目标成本审批后15天 | Q23: 方案版目标成本审批后15天 | R23: 方案版目标成本审批后15天 | S23: 方案版目标成本审批后15天 | T23: 施工图版目标成本审批确定后一个月内 项目合约规划 | U23: 1、GTBO41100-2021 《项目运营手册成本弦》
C24: 13 | D24: 二级 | E24: 样板区精装修方案设计完成 | F24: 精装修 | L24: =L89-140 -> 44999 | M24: 开放前140天 | N24: 开放前140天 | O24: 开放前140天 | P24: 开放前140天 | Q24: 开放前140天 | R24: 开放前140天 | S24: 开放前140天 | T24: 1、样板区精装修方案设计成果； 2、绿城管理集团图审核心点审查表 ； 3、方案评审会会议纪要； | U24: 1、GTBO24100-2021 《项目运营手册设计弦之精装修设计分弦》； 2、GTBP43002-2020 《住宅类项目室内方案设计评审要点》； 3、各类管控主体《管理审批权限表》；
A25: 2 | D25: 里程碑 | E25: 取得规划建筑设计方案批复 | F25: 前期 | L25: 44972 | M25: T0后70天 | N25: T0后70天 | O25: T0后75天 | P25: T0后75天 | Q25: T0后75天 | R25: T0后75天 | S25: T0后75天 | T25: 方案批复文件
C26: 14 | D26: 二级 | E26: 基坑方案设计完成并评审 | F26: 设计 | L26: =L25+5 -> 44977 | M26: 方案批复后5天内 | N26: 方案批复后5天内 | O26: 方案批复后5天内 | P26: 方案批复后5天内 | Q26: 方案批复后5天内 | R26: 方案批复后5天内 | S26: 方案批复后5天内 | T26: 1、评审会议纪要 2、预评审意见表 3、意见落实情况表 4、图纸资料 | U26: 1、GTBO21100-2021 《项目运营手册设计弦之规划设计分弦》 2、GTBG92004-2017 《建筑基坑及边坡工程管理标准》
C27: 15 | D27: 二级 | E27: 桩基施工图完成（首开区） | F27: 设计 | L27: =L25+7 -> 44979 | M27: 方案批复后7天内 | N27: 方案批复后7天内 | O27: 方案批复后7天内 | P27: 方案批复后7天内 | Q27: 方案批复后7天内 | R27: 方案批复后7天内 | S27: 方案批复后7天内
C28: 16 | D28: 二级 | E28: 桩基工程合同签订 | F28: 成本 | L28: =L25+30 -> 45002 | M28: 方案批复后30天内 | N28: 方案批复后30天内 | O28: 方案批复后30天内 | P28: 方案批复后30天内 | Q28: 方案批复后30天内 | R28: 方案批复后30天内 | S28: 方案批复后30天内 | T28: 合同流转完成，提交流程审批单 | U28: 1、GTBG91400-2020 《施工供方管理标准》
C29: 17 | D29: 二级 | E29: 售楼处建筑施工图完成 | F29: 设计 | L29: =IF(前置信息!$B$8<=4,L82-130,IF(AND(前置信息!$B$8>11,前置信息!$B$8<27),L82-130,L82-120)) -> 44994 | M29: 开放前130天 | N29: 开放前130天 | O29: 开放前120天 | P29: 开放前120天 | Q29: 开放前120天 | R29: 开放前120天 | S29: 开放前120天 | T29: 完成施工图，提交工程施工；提供设计成果确认单
C30: 18 | D30: 二级 | E30: 售楼处开工 | F30: 工程 | L30: =L82-125 -> 44999 | M30: 开放前125天 | N30: 开放前125天 | O30: 开放前125天 | P30: 开放前125天 | Q30: 开放前125天 | R30: 开放前125天 | S30: 开放前125天 | T30: 售楼处桩基或土方开始大面施工
B31: 8 | D31: 一级 | E31: 全景计划评审 | F31: 运营 | L31: =L25+15 -> 44987 | M31: 方案批复后15天内 | N31: 方案批复后15天内 | O31: 方案批复后15天内 | P31: 方案批复后15天内 | Q31: 方案批复后15天内 | R31: 方案批复后15天内 | S31: 方案批复后15天内 | T31: 方案批复后15天内 | U31: GTBO84100-2021《项目运营手册运营管理弦》
C32: 19 | D32: 二级 | E32: 样板区景观施工图设计完成并通过评审 | F32: 景观 | L32: =L82-125 -> 44999 | M32: 售楼处开放前125天 | N32: 售楼处开放前125天 | O32: 售楼处开放前125天 | P32: 售楼处开放前125天 | Q32: 开放前125天 | R32: 售楼处开放前125天 | S32: 售楼处开放前125天 | T32: 1、景观样板区施工图设计成果； 2、景观样板区施工图评审会会议纪要； 3、绿城管理集团图审核心点审查表； | U32: 1、GTBO23100-2021 《项目运营手册设计弦之景观设计分弦》； 2、GTBP33100-2020 《景观设计评审要点》； 3、各类管控主体《管理审批权限表》； 4、GTBP34001-2017 《景观重要节点标准图集》；
C33: 20 | D33: 二级 | E33: 样板房建筑施工图完成 | F33: 设计 | L33: =L89-135 -> 45004 | M33: 样板房开放前135天 | N33: 样板房开放前135天 | O33: 样板房开放前135天 | P33: 样板房开放前135天 | Q33: 样板房开放前135天 | R33: 样板房开放前135天 | S33: 样板房开放前135天 | T33: 完成施工图，提交工程施工；提供设计成果确认单
C34: 21 | D34: 二级 | E34: 工程策划完成 | F34: 工程 | L34: =IF(前置信息!$B$8<=4,L52-15,IF(AND(前置信息!$B$8>11,前置信息!$B$8<27),L52-15,L16+15)) -> 44989 | M34: 开工前15天 | N34: 开工前15天 | O34: 经营策划会后15天 | P34: 经营策划会后15天 | Q34: 经营策划会后15天 | R34: 经营策划会后15天 | S34: 经营策划会后15天 | T34: 1、工程策划书 2、目标责任分解表 | U34: 1、GTBO31100-2017B《项目运营手册工程弦之建安分弦》
C35: 22 | D35: 二级 | E35: 软装设计单位选择（含方案评审） | F35: 精装修 | L35: =IF(前置信息!$B$8<=4,L82-120,IF(AND(前置信息!$B$8>11,前置信息!$B$8<27),L82-120,L82-90)) -> 45004 | M35: 售楼处开放前120天 | N35: 售楼处开放前120天 | O35: 售楼处开放前90天 | P35: 售楼处开放前90天 | Q35: 开放前90天 | R35: 售楼处开放前90天 | S35: 售楼处开放前90天 | T35: 合同流转完成，提交流程审批单 | U35: 1、GTBG91400-2020 《施工供方管理标准》
B36: 9 | D36: 一级 | E36: 营销全案策略会 | F36: 营销 | L36: =IF(前置信息!$B$8<=4,L93-150,IF(AND(前置信息!$B$8>11,前置信息!$B$8<27),L93-150,L93-120)) -> 45004 | M36: 首次开盘前150天 | N36: 首次开盘前150天 | O36: 首次开盘前120天 | P36: 首次开盘前120天 | Q36: 首次开盘前120天 | R36: 首次开盘前120天 | S36: 首次开盘前120天 | T36: 营销全案策略评审纪要及相关成果 | U36: 《项目首次开盘方案》
C37: 23 | D37: 二级 | E37: 桩基施工完成（首开区） | F37: 工程 | L37: =L28+15 -> 45017 | M37: 桩基工程合同签订后15天 | N37: 桩基工程合同签订后15天 | O37: 桩基工程合同签订后15天 | P37: 桩基工程合同签订后15天 | Q37: 桩基工程合同签订后15天 | R37: 桩基工程合同签订后15天 | S37: 桩基工程合同签订后15天 | T37: 首开区桩基施工完成并具备土方开挖条件
B38: 10 | D38: 一级 | E38: 取得《建设工程规划许可证》 | F38: 前期 | L38: =L25+25 -> 44997 | M38: 方案批复后25天内 | N38: 方案批复后25天内 | O38: 方案批复后25天 | P38: 方案批复后25天 | Q38: 方案批复后25天 | R38: 方案批复后25天 | S38: 方案批复后25天 | T38: 《建设工程规划许可证》
B39: 11 | D39: 一级 | E39: 全景计划指标委托方签确 | F39: 运营 | L39: =L31+10 -> 44997 | M39: 全景计划评审后10天内 | N39: 全景计划评审后10天内 | O39: 全景计划评审后10天内 | P39: 全景计划评审后10天内 | Q39: 全景计划评审后10天内 | R39: 全景计划评审后10天内 | S39: 全景计划评审后10天内 | T39: 全景计划评审后10天内
B40: 12 | D40: 一级 | E40: 方案版目标成本审批完成 | F40: 成本 | L40: =L25+30 -> 45002 | M40: 方案批复后30天内 | N40: 方案批复后30天内 | O40: 方案批复后30天内 | P40: 方案批复后30天内 | Q40: 方案批复后30天内 | R40: 方案批复后30天内 | S40: 方案批复后30天内 | T40: 方案批复后30天内 流程审批完成，提交流程审批单 | U40: 1、GTBO41100-2021 《项目运营手册成本弦》
B41: 13 | D41: 一级 | E41: 批量建筑施工图设计完成 | F41: 设计 | L41: =L25+30 -> 45002 | M41: 方案批复后30天 | N41: 方案批复后30天 | O41: 方案批复后30天 | P41: 方案批复后30天 | Q41: 方案批复后30天 | R41: 方案批复后30天 | S41: 方案批复后30天 | T41: 1、评审会议纪要 2、施工图图审单位意见 3、图纸资料 | U41: 1、GTBO21100-2021 《项目运营手册设计弦之规划设计分弦》 2、GTBG92601-2018 《同步设计操作手册》 3、GTBP13004-2020 《住宅项目建筑施工图评审要点》 4、GTBP5200X 《建筑工程营造工艺工法标准-XX篇》
...

Sheet Sheet1
A40: 容积率 | B40: 地下室层数 | C40: 桩基形式 | D40: 有无开发贷 | E40: 水平支撑层数 | F40: 首开示范区面积 | G40: 地上最高层数 | H40: 有无架空层 | I40: 交付形式 | J40: 有无户内改造 | K40: 外立面形式
A41: 小于2.5 | B41: 1 | C41: 管桩 | D41: 有 | E41: 0 | F41: 小于7000㎡ | H41: 有 | I41: 毛坯 | J41: 有 | K41: 保温涂料
A42: 大于2.5 | B42: 2 | C42: 灌注桩 | D42: 无 | E42: 1 | F42: 大于7000㎡ | H42: 无 | I42: 精装 | J42: 无 | K42: 保温涂料+铝板
E43: 2
E44: 3

Sheet Sheet2
A2: 46217
A3: 46995
A4: =(A3-A2)/30 -> 25.933333
